Workbook
Name PlageDynamique: OFFSET(#REF!,,,COUNTIF(#REF!,"?*")-1)
Name SME_2019: '[1]Grille Salaire'!$AB$1

Sheet DIAME CNAPS
A1: Noms | B1: Prénoms | C1: Octobre | E1: Novembre | G1: Décembre | I1: Total charge CNaPS | J1: Total FMFP
C2: Charge CNaPS | D2: FMFP | E2: Charge CNaPS | F2: FMFP | G2: Charge CNaPS | H2: FMFP
A3: RABERIAKA | B3: Gaëtan Henri | C3: 217689.36 | D3: 15549.24 | E3: 217689.36 | F3: 15549.24 | G3: 217689.36 | H3: 15549.24 | I3: 653068.08 | J3: 46647.72
A4: GALY | B4: Luigi Florentin | C4: 103143.88 | D4: 7367.42 | E4: 103143.88 | F4: 7367.42 | G4: 103143.88 | H4: 7367.42 | I4: 309431.64 | J4: 22102.26
A5: RAKOTOELINORO | B5: Onjanandrianina Jean René | C5: 195770.26 | D5: 13983.59 | E5: 195770.26 | F5: 13983.59 | G5: 195770.26 | H5: 13983.59 | I5: 587310.78 | J5: 41950.77
A6: RANDRIANANTENAINA | B6: Alain | C6: 89356.12 | D6: 6382.58 | E6: 89356.12 | F6: 6382.58 | G6: 89356.12 | H6: 6382.58 | I6: 268068.36 | J6: 19147.74
A7: RAOUL | C7: 78361.22 | D7: 5597.23 | E7: 75172.72 | F7: 5369.48 | G7: 62646.5 | H7: 4474.75 | I7: 216180.44 | J7: 15441.46
A8: RAVOLAMBAHOAKA | B8: Benedictine | C8: 17393.88 | D8: 1242.42 | E8: 17393.88 | F8: 1242.42 | G8: 17393.88 | H8: 1242.42 | I8: 52181.64 | J8: 3727.26
A9: RAZAFINTSALAMA | B9: Herizo Nandrianintsoa | C9: 294201.6 | D9: 21014.4 | E9: 294201.6 | F9: 21014.4 | G9: 294201.6 | H9: 21014.4 | I9: 882604.8 | J9: 63043.2
A10: RENE | C10: 76083.7 | D10: 5434.55 | E10: 62646.5 | F10: 4474.75 | G10: 77222.46 | H10: 5515.89 | I10: 215952.66 | J10: 15425.19
A11: TSIZAFY | B11: Arnaud Victorien | C11: 97840.96 | D11: 6988.64 | E11: 97840.96 | F11: 6988.64 | G11: 97840.96 | H11: 6988.64 | I11: 293522.88 | J11: 20965.92
A12: VELONASY | C12: 62646.5 | D12: 4474.75 | E12: 76083.7 | F12: 5434.55 | G12: 74033.96 | H12: 5288.14 | I12: 212764.16 | J12: 15197.44
A13: RANDRIAMPENOMANANA | B13: Harinelina Faly | C13: 151224.78 | D13: 10801.77 | E13: 151224.78 | F13: 10801.77 | G13: 151224.78 | H13: 10801.77 | I13: 453674.34 | J13: 32405.31
A14: RAHARIZARASOA | B14: Manitrasina Sahoby | C14: 56989.94 | D14: 4070.71 | E14: 56989.94 | F14: 4070.71 | G14: 56989.94 | H14: 4070.71 | I14: 170969.82 | J14: 12212.13
A15: DAHY | B15: Christophe | C15: 119406.56 | D15: 8529.04 | E15: 119406.56 | F15: 8529.04 | G15: 119406.56 | H15: 8529.04 | I15: 358219.68 | J15: 25587.12
A16: LAMA | B16: Francisco Anicet | C16: 72121.28 | D16: 5151.52 | E16: 72121.28 | F16: 5151.52 | G16: 72121.28 | H16: 5151.52 | I16: 216363.84 | J16: 15454.56
A17: TOTO | B17: Rodin | C17: 70790.16 | D17: 5056.44 | E17: 70790.16 | F17: 5056.44 | G17: 70790.16 | H17: 5056.44 | I17: 212370.48 | J17: 15169.32
A18: BIAKA | B18: Marie Jeanne | C18: 18808.02 | D18: 1343.43 | E18: 18808.02 | F18: 1343.43 | G18: 18808.02 | H18: 1343.43 | I18: 56424.06 | J18: 4030.29
A19: TSARAVINTANA | B19: Francot | C19: 58404.08 | D19: 4171.72 | E19: 58404.08 | F19: 4171.72 | G19: 31148.88 | H19: 2224.92 | I19: 147957.04 | J19: 10568.36
A20: PEROLIN | C20: 58404.08 | D20: 4171.72 | E20: 58404.08 | F20: 4171.72 | G20: 58404.08 | H20: 4171.72 | I20: 175212.24 | J20: 12515.16
A21: SAMIANGALY | B21: Valerie Avotranirina | C21: 159356.12 | D21: 11382.58 | E21: 159356.12 | F21: 11382.58 | G21: 159356.12 | H21: 11382.58 | I21: 478068.36 | J21: 34147.74
A22: RAMANJAKAMBALO | B22: Judicael | C22: 44324.42 | D22: 3166.03 | I22: 44324.42 | J22: 3166.03
A23: TSIRA | B23: Jean Christian | C23: 113219.68 | D23: 8087.12 | E23: 113219.68 | F23: 8087.12 | G23: 113219.68 | H23: 8087.12 | I23: 339659.04 | J23: 24261.36
A24: KWAN_KAI-TON | B24: Rasoanirina Lydie | C24: 158648.98 | D24: 11332.07 | E24: 158648.98 | F24: 11332.07 | G24: 158648.98 | H24: 11332.07 | I24: 475946.94 | J24: 33996.21
A25: RANDRIAMINOHARINIRINA | B25: Herinalaina | C25: 158295.48 | D25: 11306.82 | E25: 158295.48 | F25: 11306.82 | G25: 158295.48 | H25: 11306.82 | I25: 474886.44 | J25: 33920.46
A26: HERIMAMINAVALONA | B26: Fifaliana | C26: 56989.94 | D26: 4070.71 | E26: 56989.94 | F26: 4070.71 | G26: 56989.94 | H26: 4070.71 | I26: 170969.82 | J26: 12212.13
A27: MAMONJISOA | B27: Heriniaina André | C27: 56989.94 | D27: 4070.71 | E27: 56989.94 | F27: 4070.71 | G27: 56989.94 | H27: 4070.71 | I27: 170969.82 | J27: 12212.13
A28: VICTORIEN | B28: Angeliot | C28: 56989.94 | D28: 4070.71 | E28: 56989.94 | F28: 4070.71 | G28: 56989.94 | H28: 4070.71 | I28: 170969.82 | J28: 12212.13
A29: SANDRINE | C29: 107032.8 | D29: 7645.2 | E29: 107032.8 | F29: 7645.2 | G29: 107032.8 | H29: 7645.2 | I29: 321098.4 | J29: 22935.6
A30: SOMA | B30: Ginot | C30: 48249.6 | D30: 3446.4 | E30: 60312 | F30: 4308 | G30: 38599.68 | H30: 2757.12 | I30: 147161.28 | J30: 10511.52
A31: VOLAHAINGO | B31: Frida Samuella | C31: 56989.94 | D31: 4070.71 | E31: 56989.94 | F31: 4070.71 | G31: 56989.94 | H31: 4070.71 | I31: 170969.82 | J31: 12212.13
A32: SEDRANIAINA | B32: Santatra Irène | C32: 56989.94 | D32: 4070.71 | E32: 56989.94 | F32: 4070.71 | G32: 56989.94 | H32: 4070.71 | I32: 170969.82 | J32: 12212.13
A33: BAKOARISOA | B33: Hanitriniaina | C33: 294201.6 | D33: 21014.4 | E33: 294201.6 | F33: 21014.4 | G33: 294201.6 | H33: 21014.4 | I33: 882604.8 | J33: 63043.2
A34: RAHARISON | B34: Danny | C34: 32298.84 | D34: 2307.06 | E34: 34093.22 | F34: 2435.23 | G34: 32298.84 | H34: 2307.06 | I34: 98690.9 | J34: 7049.35
A35: FENOMANANA | B35: Syressi Tilamb | C35: 49919.24 | D35: 3565.66 | E35: 49919.24 | F35: 3565.66 | G35: 49919.24 | H35: 3565.66 | I35: 149757.72 | J35: 10696.98
A36: MAROLAHY | B36: Stanislas | C36: 49919.24 | D36: 3565.66 | E36: 49919.24 | F36: 3565.66 | G36: 49919.24 | H36: 3565.66 | I36: 149757.72 | J36: 10696.98
A37: BERY | B37: Jerson Alexandre | C37: 49919.24 | D37: 3565.66 | E37: 49919.24 | F37: 3565.66 | G37: 49919.24 | H37: 3565.66 | I37: 149757.72 | J37: 10696.98
A38: BIHANONA | B38: Elito | E38: 49919.24 | F38: 3565.66 | G38: 49919.24 | H38: 3565.66 | I38: 99838.48 | J38: 7131.32
A39: RAZAFINDRIANTSY | B39: Pierrot Carlos | E39: 49919.24 | F39: 3565.66 | G39: 49919.24 | H39: 3565.66 | I39: 99838.48 | J39: 7131.32
A40: YOURI | B40: Vincent | E40: 42848.54 | F40: 3060.61 | G40: 42848.54 | H40: 3060.61 | I40: 85697.08 | J40: 6121.22
...

Sheet EMPLOYEUR
A2: RENSEIGNEMENTS SUR L'EMPLOYEUR :
B4: N° MATRICULE | C4: 9C2137
B5: RAISON SOCIALE | C5: ONG SOAKOJA
B6: NIF | C6: 3003101957 | D6: du
B7: RCS | D7: du
B8: STAT | C8: 8810132201800019310 | D8: du
B9: ADRESSE | C9: BEMASOANDRO ANKAZOMIANKO VAVATENINA
B10: N° Téléphone | C10: 034 85 214 08
B11: Adresse mail | C11: ong.soakoja@gmail.com
A13: COTISATIONS :
B14: Période et Année | C14: 45566 | D14: Ex: 01-2011
B15: Mode de paiemnt | C15: Virement bancaire
B16: Référence
B17: Taux Employeur | C17: 0.13
B18: Taux Travailleur | C18: 0.01
A20: MOIS CONCERNES : | C20: =EDATE(C14,0) -> 45566 | D20: =EDATE(C14,1) -> 45597 | E20: =EDATE(C14,2) -> 45627
A23: RECAPITULATION : | C23: Mois 1 | D23: Mois 2 | E23: Mois 3 | F23: TOTAUX
B24: Effectif mensuel (OBLIGATOIRE) | C24: =COUNTIF([1]!liste_paiement[Mois paiement],EMPLOYEUR!C$20) -> 35 | D24: =COUNTIF([1]!liste_paiement[Mois paiement],EMPLOYEUR!D$20) -> 38 | E24: =COUNTIF([1]!liste_paiement[Mois paiement],EMPLOYEUR!E$20) -> 38
B25: Totaux Salaires plafonnés | C25: =SUMIF([1]!liste_paiement[Mois paiement],EMPLOYEUR!C$20,[1]!liste_paiement[Salaires plafonnés]) -> 23812058 | D25: =SUMIF([1]!liste_paiement[Mois paiement],EMPLOYEUR!D$20,[1]!liste_paiement[Salaires plafonnés]) -> 24896911 | E25: =SUMIF([1]!liste_paiement[Mois paiement],EMPLOYEUR!E$20,[1]!liste_paiement[Salaires plafonnés]) -> 24534326 | F25: =SUM(C25:E25) -> 73243295
B26: Cotisations Employeur | C26: =SUMIF([1]!liste_paiement[Mois paiement],EMPLOYEUR!C$20,[1]!liste_paiement[CNaPS])*13 -> 3146901.9 | D26: =SUMIF([1]!liste_paiement[Mois paiement],EMPLOYEUR!D$20,[1]!liste_paiement[CNaPS])*13 -> 3287932.8 | E26: =SUMIF([1]!liste_paiement[Mois paiement],EMPLOYEUR!E$20,[1]!liste_paiement[CNaPS])*13 -> 3240796.8 | F26: =SUM(C26:E26) -> 9675631.6
B27: Cotisations travailleurs | C27: =SUMIF([1]!liste_paiement[Mois paiement],EMPLOYEUR!C$20,[1]!liste_paiement[CNaPS]) -> 242069.38 | D27: =SUMIF([1]!liste_paiement[Mois paiement],EMPLOYEUR!D$20,[1]!liste_paiement[CNaPS]) -> 252917.91 | E27: =SUMIF([1]!liste_paiement[Mois paiement],EMPLOYEUR!E$20,[1]!liste_paiement[CNaPS]) -> 249292.06 | F27: =SUM(C27:E27) -> 744279.35
A30: COTISATIONS FMFP
B31: Période et Année | C31: 02-2023
B32: Taux Employeur | C32: 1 %
A34: RECAPITULATION
B35: MOIS CONCERNE | C35: =EDATE(C14,0) -> 45566 | D35: =EDATE(C14,1) -> 45597 | E35: =EDATE(C14,2) -> 45627 | F35: TOTAUX
B36: Effectif mensuel (OBLIGATOIRE) | C36: =C24 -> 35 | D36: =D24 -> 38 | E36: =E24 -> 38 | F36: 0
B37: Totaux Salaires plafonnés | C37: =C25 -> 23812058 | D37: =D25 -> 24896911 | E37: =E25 -> 24534326 | F37: =SUM(C37:E37) -> 73243295
B38: Cotisations Employeur | C38: =SUMIF([1]!liste_paiement[Mois paiement],EMPLOYEUR!C$20,[1]!liste_paiement[CNaPS]) -> 242069.38 | D38: =SUMIF([1]!liste_paiement[Mois paiement],EMPLOYEUR!D$20,[1]!liste_paiement[CNaPS]) -> 252917.91 | E38: =SUMIF([1]!liste_paiement[Mois paiement],EMPLOYEUR!E$20,[1]!liste_paiement[CNaPS]) -> 249292.06 | F38: =SUM(C38:E38) -> 744279.35
B42: ** Reporter ci-dessus les totaux obtenus dans les onglets Mois 1, 2 et 3.

Sheet Annexe DNS
B1: Matricule | C1: CIN | D1: Nom | E1: Prénom(s) | F1: Réf. Employeur | G1: Embauche | H1: Débauche | I1: M1 | M1: M2 | Q1: M3 | U1: Occasionnel | V1: Téléphone | W1: Email
A2: N° employé | I2: Salaire | J2: Avantage | K2: TP | L2: Plafond | M2: Salaire | N2: Avantage | O2: TP | P2: Plafond | Q2: Salaire | R2: Avantage | S2: TP | T2: Plafond
A3: S05 | B3: 860928004436 | C3: 301051014050 | D3: GALY | E3: Luigi Florentin | F3: S9 | G3: 43647 | H3: / | I3: 0 | J3: 0 | K3: 243 | L3: 2101440 | M3: 0 | N3: 0 | O3: 243 | P3: 2101440 | Q3: 0 | R3: 0 | S3: 243 | T3: 2101440 | U3: N | V3: 0346166200
A4: S24 | B4: 870101049411 | C4: 114171010430 | D4: DAHY | E4: Christophe | F4: S10 | G4: 44013 | H4: / | I4: 0 | J4: 0 | K4: 243 | L4: 2101440 | M4: 0 | N4: 0 | O4: 243 | P4: 2101440 | Q4: 0 | R4: 0 | S4: 243 | T4: 2101440 | U4: N | V4: 0346059830
A5: S34 | B5: 872926001528 | C5: 315012021066 | D5: SAMIANGALY | E5: Valerie Avotranirina | F5: S25 | G5: 44270 | H5: / | I5: 0 | J5: 0 | K5: 243 | L5: 2101440 | M5: 0 | N5: 0 | O5: 243 | P5: 2101440 | Q5: 0 | R5: 0 | S5: 243 | T5: 2101440 | U5: N | V5: 0345938882
A6: S40 | B6: 880505006093 | C6: 313011021032 | D6: RANDRIAMINOHARINIRINA | E6: Herinalaina | F6: S31 | G6: 44566 | H6: 45682 | I6: 0 | J6: 0 | K6: 0 | L6: 2101440 | M6: 0 | N6: 0 | O6: 0 | P6: 2101440 | Q6: 0 | R6: 0 | S6: 0 | T6: 2101440 | U6: N | V6: 0341059605
A7: S46 | B7: 900502008862 | C7: 305011023865 | D7: VICTORIEN | E7: Angeliot | F7: S57 | G7: 44713 | H7: / | I7: 0 | J7: 0 | K7: 243 | L7: 2101440 | M7: 0 | N7: 0 | O7: 243 | P7: 2101440 | Q7: 0 | R7: 0 | S7: 243 | T7: 2101440 | U7: N | V7: 0348771682
A8: S19 | B8: 902310004794 | C8: 305011020286 | D8: RANDRIAMPENOMANANA | E8: Harinelina Faly | F8: S42 | G8: 43900 | H8: / | I8: 0 | J8: 0 | K8: 243 | L8: 2101440 | M8: 0 | N8: 0 | O8: 243 | P8: 2101440 | Q8: 0 | R8: 0 | S8: 243 | T8: 2101440 | U8: N | V8: 0342431748
A9: S32 | B9: 910101108553 | C9: 315051019810 | D9: TSARAVINTANA | E9: Francot | F9: S43 | G9: 44105 | H9: 45672 | I9: 0 | J9: 0 | K9: 243 | L9: 2101440 | M9: 0 | N9: 0 | O9: 243 | P9: 2101440 | Q9: 222492 | R9: 0 | S9: 129.6 | T9: 2101440 | U9: N | V9: 0346732461
A10: S39 | B10: 913222003933 | C10: 312012020745 | D10: KWAN_KAI-TON | E10: Rasoanirina Lydie | F10: S2 | G10: 44566 | H10: / | I10: 0 | J10: 0 | K10: 243 | L10: 2101440 | M10: 0 | N10: 0 | O10: 243 | P10: 2101440 | Q10: 0 | R10: 0 | S10: 243 | T10: 2101440 | U10: N | V10: 0346845550
A11: S64 | B11: 910817005636 | C11: 318011030815 | D11: FENOMANANA | E11: Syressi Tilamb | F11: S3 | G11: 45323 | H11: / | I11: 0 | J11: 0 | K11: 243 | L11: 2101440 | M11: 0 | N11: 0 | O11: 243 | P11: 2101440 | Q11: 0 | R11: 0 | S11: 243 | T11: 2101440 | U11: N | V11: 0347339392
A12: S42 | B12: 000819002120 | C12: 106501017655 | D12: HERIMAMINAVALONA | E12: Fifaliana | F12: S32 | G12: 44652 | H12: / | I12: 0 | J12: 0 | K12: 243 | L12: 2101440 | M12: 0 | N12: 0 | O12: 243 | P12: 2101440 | Q12: 0 | R12: 0 | S12: 243 | T12: 2101440 | U12: N | V12: 0346557563
A13: S30 | B13: 662303003212 | C13: 315012010015 | D13: BIAKA | E13: Marie Jeanne | F13: S33 | G13: 44013 | H13: / | I13: 0 | J13: 0 | K13: 44 | L13: 2101440 | M13: 0 | N13: 0 | O13: 44 | P13: 2101440 | Q13: 0 | R13: 0 | S13: 44 | T13: 2101440 | U13: N | V13: 0389724197
A14: S17 | B14: 680101123586 | C14: 315051005651 | D14: VELONASY | F14: S48 | G14: 43647 | H14: / | I14: 0 | J14: 0 | K14: 243 | L14: 2101440 | M14: 0 | N14: 0 | O14: 243 | P14: 2101440 | Q14: 0 | R14: 0 | S14: 243 | T14: 2101440 | U14: N | V14: 0345563316
A15: S11 | B15: 690101071333 | C15: 315011012731 | D15: RAOUL | F15: S28 | G15: 43647 | H15: / | I15: 0 | J15: 0 | K15: 243 | L15: 2101440 | M15: 0 | N15: 0 | O15: 243 | P15: 2101440 | Q15: 0 | R15: 0 | S15: 243 | T15: 2101440 | U15: N | V15: 0383954516
A16: S01 | B16: 710809002458 | C16: 301091003840 | D16: RABERIAKA | E16: Gaëtan Henri | F16: S45 | G16: 43313 | H16: / | I16: 0 | J16: 0 | K16: 243 | L16: 2101440 | M16: 0 | N16: 0 | O16: 243 | P16: 2101440 | Q16: 0 | R16: 0 | S16: 243 | T16: 2101440 | U16: N | V16: 0347118414
A17: S14 | B17: 730926003826 | C17: 315011014867 | D17: RENE | F17: S46 | G17: 43647 | H17: / | I17: 0 | J17: 0 | K17: 243 | L17: 2101440 | M17: 0 | N17: 0 | O17: 243 | P17: 2101440 | Q17: 0 | R17: 0 | S17: 243 | T17: 2101440 | U17: N | V17: 0384838550
A18: S36 | B18: 750318006073 | C18: 301091007383 | D18: RAMANJAKAMBALO | E18: Judicael | F18: S16 | G18: 44470 | H18: 45580 | I18: 316603 | J18: 0 | K18: 121.5 | L18: 2101440 | M18: 0 | N18: 0 | O18: 0 | P18: 2101440 | Q18: 0 | R18: 0 | S18: 0 | T18: 2101440 | U18: N | V18: 0344387533
A19: S16 | B19: 810803005367 | C19: 315011018148 | D19: TSIZAFY | E19: Arnaud Victorien | F19: S26 | G19: 43647 | H19: / | I19: 0 | J19: 0 | K19: 243 | L19: 2101440 | M19: 0 | N19: 0 | O19: 243 | P19: 2101440 | Q19: 0 | R19: 0 | S19: 243 | T19: 2101440 | U19: N | V19: 0349549718
A20: S12 | B20: 822101041870 | C20: 315012020356 | D20: RAVOLAMBAHOAKA | E20: Benedictine | F20: S40 | G20: 43647 | H20: / | I20: 0 | J20: 0 | K20: 44 | L20: 2101440 | M20: 0 | N20: 0 | O20: 44 | P20: 2101440 | Q20: 0 | R20: 0 | S20: 44 | T20: 2101440 | U20: N | V20: 0
A21: S13 | B21: 840712004464 | C21: 108051009775 | D21: RAZAFINTSALAMA | E21: Herizo Nandrianintsoa | F21: S50 | G21: 43647 | H21: / | I21: 0 | J21: 0 | K21: 243 | L21: 2101440 | M21: 0 | N21: 0 | O21: 243 | P21: 2101440 | Q21: 0 | R21: 0 | S21: 243 | T21: 2101440 | U21: N | V21: 0348521408
A22: S54 | B22: 842123004658 | C22: 305012013363 | D22: VOLAHAINGO | E22: Frida Samuella | F22: S39 | G22: 44845 | H22: / | I22: 0 | J22: 0 | K22: 243 | L22: 2101440 | M22: 0 | N22: 0 | O22: 243 | P22: 2101440 | Q22: 0 | R22: 0 | S22: 243 | T22: 2101440 | U22: N | V22: 0382203653
A23: S38 | B23: 920919005564 | C23: 305011024168 | D23: TSIRA | E23: Jean Christian | F23: S56 | G23: 44533 | H23: / | I23: 0 | J23: 0 | K23: 243 | L23: 2101440 | M23: 0 | N23: 0 | O23: 243 | P23: 2101440 | Q23: 0 | R23: 0 | S23: 243 | T23: 2101440 | U23: N | V23: 0342516349
A24: S08 | B24: 920925003602 | C24: 201031036732 | D24: RAKOTOELINORO | E24: Onjanandrianina Jean René | F24: S54 | G24: 43654 | H24: / | I24: 0 | J24: 0 | K24: 243 | L24: 2101440 | M24: 0 | N24: 0 | O24: 243 | P24: 2101440 | Q24: 0 | R24: 0 | S24: 243 | T24: 2101440 | U24: N | V24: 0346839275
A25: S26 | B25: 931225004475 | C25: 305011031220 | D25: LAMA | E25: Francisco Anicet | F25: S38 | G25: 44013 | H25: / | I25: 0 | J25: 0 | K25: 243 | L25: 2101440 | M25: 0 | N25: 0 | O25: 243 | P25: 2101440 | Q25: 0 | R25: 0 | S25: 243 | T25: 2101440 | U25: N | V25: 0346987900
A26: S61 | B26: 305012036357 | C26: 305011026202 | D26: RAHARISON | E26: Danny | F26: S19 | G26: 45231 | H26: / | I26: 0 | J26: 0 | K26: 120 | L26: 2101440 | M26: 0 | N26: 0 | O26: 120 | P26: 2101440 | Q26: 0 | R26: 0 | S26: 120 | T26: 2101440 | U26: N | V26: 0347571774
A27: S67 | B27: 940814005961 | C27: 305011029482 | D27: BERY | E27: Jerson Alexandre | F27: S8 | G27: 45352 | H27: / | I27: 0 | J27: 0 | K27: 243 | L27: 2101440 | M27: 0 | N27: 0 | O27: 243 | P27: 2101440 | Q27: 0 | R27: 0 | S27: 243 | T27: 2101440 | U27: N | V27: 0341761222
A28: S10 | B28: 950118001239 | C28: 315031008057 | D28: RANDRIANANTENAINA | E28: Alain | F28: S1 | G28: 43647 | H28: / | I28: 0 | J28: 0 | K28: 243 | L28: 2101440 | M28: 0 | N28: 0 | O28: 243 | P28: 2101440 | Q28: 0 | R28: 0 | S28: 243 | T28: 2101440 | U28: N | V28: 0345063639
A29: S50 | B29: 952711003017 | C29: 305012030611 | D29: SANDRINE | F29: S30 | G29: 44725 | H29: / | I29: 0 | J29: 0 | K29: 243 | L29: 2101440 | M29: 0 | N29: 0 | O29: 243 | P29: 2101440 | Q29: 0 | R29: 0 | S29: 243 | T29: 2101440 | U29: N | V29: 0348236771
A30: S28 | B30: 960101063306 | C30: 305011037183 | D30: TOTO | E30: Rodin | F30: S12 | G30: 44013 | H30: / | I30: 0 | J30: 0 | K30: 243 | L30: 2101440 | M30: 0 | N30: 0 | O30: 243 | P30: 2101440 | Q30: 0 | R30: 0 | S30: 243 | T30: 2101440 | U30: N | V30: 0342425815
A31: S43 | B31: 970529004452 | C31: 103311003453 | D31: MAMONJISOA | E31: Heriniaina André | F31: S11 | G31: 44652 | H31: / | I31: 0 | J31: 0 | K31: 243 | L31: 2101440 | M31: 0 | N31: 0 | O31: 243 | P31: 2101440 | Q31: 0 | R31: 0 | S31: 243 | T31: 2101440 | U31: N | V31: 0381770988
A32: S33 | B32: 970608003979 | C32: 315011029815 | D32: PEROLIN | F32: S14 | G32: 44137 | H32: / | I32: 0 | J32: 0 | K32: 243 | L32: 2101440 | M32: 0 | N32: 0 | O32: 243 | P32: 2101440 | Q32: 0 | R32: 0 | S32: 243 | T32: 2101440 | U32: N | V32: 0340809115
A33: S20 | B33: 981124001527 | C33: 103431003278 | D33: RAHARIZARASOA | E33: Manitrasina Sahoby | F33: S17 | G33: 43921 | H33: / | I33: 0 | J33: 0 | K33: 243 | L33: 2101440 | M33: 0 | N33: 0 | O33: 243 | P33: 2101440 | Q33: 0 | R33: 0 | S33: 243 | T33: 2101440 | U33: N | V33: 0345973648
A34: S56 | B34: 982523003831 | C34: 305012036357 | D34: SEDRANIAINA | E34: Santatra Irène | F34: S6 | G34: 44987 | H34: / | I34: 0 | J34: 0 | K34: 243 | L34: 2101440 | M34: 0 | N34: 0 | O34: 243 | P34: 2101440 | Q34: 0 | R34: 0 | S34: 243 | T34: 2101440 | U34: N | V34: 0344869434
A35: S65 | B35: 990707004571 | C35: 315011034168 | D35: MAROLAHY | E35: Stanislas | F35: S34 | G35: 45323 | H35: / | I35: 0 | J35: 0 | K35: 243 | L35: 2101440 | M35: 0 | N35: 0 | O35: 243 | P35: 2101440 | Q35: 0 | R35: 0 | S35: 243 | T35: 2101440 | U35: N | V35: 0341178292
A36: S59 | B36: 842401003931 | C36: 201012011872 | D36: BAKOARISOA | E36: Hanitriniaina | F36: S24 | G36: 45108 | H36: / | I36: 0 | J36: 0 | K36: 243 | L36: 2101440 | M36: 0 | N36: 0 | O36: 243 | P36: 2101440 | Q36: 0 | R36: 0 | S36: 243 | T36: 2101440 | U36: N | V36: 0341677984
A37: S53 | B37: 940927003786 | C37: 305011026832 | D37: SOMA | E37: Ginot | F37: S58 | G37: 44805 | H37: / | I37: 0 | J37: 0 | K37: 120 | L37: 2101440 | M37: 0 | N37: 0 | O37: 120 | P37: 2101440 | Q37: 0 | R37: 0 | S37: 120 | T37: 2101440 | U37: N | V37: 0340922470
A38: S68 | B38: 950209003407 | C38: 305011031886 | D38: BIHANONA | E38: Elito | F38: S58 | G38: 45597 | H38: / | I38: 0 | J38: 0 | K38: 243 | L38: 2101440 | M38: 0 | N38: 0 | O38: 243 | P38: 2101440 | Q38: 0 | R38: 0 | S38: 243 | T38: 2101440 | U38: N | V38: 0345004020
A39: S69 | B39: 950609006301 | C39: 315011029171 | D39: RAZAFINDRIANTSY | E39: Pierrot Carlos | F39: S58 | G39: 45597 | H39: / | I39: 0 | J39: 0 | K39: 243 | L39: 2101440 | M39: 0 | N39: 0 | O39: 243 | P39: 2101440 | Q39: 0 | R39: 0 | S39: 243 | T39: 2101440 | U39: N | V39: 0344639248
A40: S70 | B40: 990310006547 | C40: 305111010829 | D40: YOURI | E40: Vincent | F40: S58 | G40: 45597 | H40: / | I40: 0 | J40: 0 | K40: 0 | L40: 2101440 | M40: 0 | N40: 0 | O40: 0 | P40: 2101440 | Q40: 0 | R40: 0 | S40: 0 | T40: 2101440 | U40: N | V40: 0342988567
...

Sheet Talon DNS
A1: C.Na.P.S | F1: Tahiry Famatsiam-bola Malagasy ho Fampandrosoana ny mPiasa | L1: Trimestre précédent | M1: =IF(MONTH(TODAY())<4,DATE(YEAR(TODAY())-1, 10,1),DATE(YEAR(TODAY()), CHOOSE(MONTH(TODAY()),10,10,10,1,1,1,4,4,4,7,7,7), 1)) -> 45839
A2: Place Ho Chi MINH Ampefiloha Antananarivo | F2: F.M.F.P
A3: --------------------- | F3: Tour Zital Ankorondrano Antananarivo
A4: BP : 23 - TEL : 22 205 20 - FAX : 22 255 96 | F4: --------------------------
A5: Site web: http://www/cnaps/mg | F5: TEL : 22 538 86 - 034 42 593 33
F6: Loi n°2017-025 du 30/01/2018 - Décret n°2018-1509 du 13/11/2018
A8: Pour les déclarations, e-mail: cnaps-dn@cnaps.mg ou Site web: http://www.cnaps.mg/ ou dossier physique à déposer aux bureaux de la CNaPS
A10: TALON DES DECLARATIONS NOMINATIVES DES SALAIRES
A11: ="Période: "&IF(MONTH(M1)=1,"1er trimestre ",IF(MONTH(M1)=4,"2e trimestre ",IF(MONTH(M1)=7,"3e trimestre ","4e trimestre ")))&YEAR(M1) -> Période: 3e trimestre 2025
A12: ="Date impérative de retour de paiement avant le : "&DAY(EOMONTH(M1,3))&" "&CHOOSE(MONTH(EOMONTH(M1,3)),"Janvier ","Février ","Mars ","Avril ","Mai ","Juin ","Juillet ","Aout ","Septembre ","Octobre ","Novembre ","Décembre ")&YEAR(EOMONTH(M1,3)) -> Date impérative de retour de paiement avant le : 31 Octobre 2025
A13: Employeur: | B13: 9C2137 | C13: ONG SOAKOJA
A14: Adresse: BEMASOANDRO ANKAZOMIANKO VAVATENINA VAVATENINA 518 | H14: Tél:
H15: E-mail:
A17: CAISSE NATIONALE DE PREVOYANCE SOCIALE | F17: FONDS MALGACHE DE FORMATION PROFESSIONNELLE
A18: C.Na.P.S | F18: tahiry Famatsiam-bola Malagasy ho Fampandrosoana ny mPiasa - F.M.F.P
A19: Code activité Employeur: 825 | F19: --------------------------------
A20: Taux de cotisation employeur: 13% | F20: Taux de cotisation employeur : 1%
A21: Taux de cotisation travailleur: 1% | F21: =A22 -> Plafond mensuel : Ar 2 101 440
A22: Plafond mensuel : Ar 2 101 440 | F22: □ 1- Textile Habillement Accessoires (THA)
F23: □ 2 - Tourisme Hôtelerie Restauration (THR)
F24: □ 3- Technologies de l'information et de la Communication (TIC)
F25: □ 4- Bâtiment Travaux Publics - Ressources Stratégiques (BTP - RS)
F26: x 5- Développement Rural (DR)
F27: □ 6- Autres Secteurs
A30: Salaire non plafonné | C30: =SUMIF([1]!liste_paiement[Trimestre paiement],$M$1,[1]!liste_paiement[Salaire brut total]) -> 0 | F30: Salaire non plafonné | I30: =C30 -> 0
A31: Salaire plafonné | C31: =SUMIF([1]!liste_paiement[Trimestre paiement],$M$1,[1]!liste_paiement[Salaires plafonnés]) -> 0 | F31: Salaire plafonné | I31: =C31 -> 0
A32: Total cotisation employeur | C32: =SUMIF([1]!liste_paiement[Trimestre paiement],$M$1,[1]!liste_paiement[CNaPS])*13 -> 0 | F32: Total cotisation formation | I32: =C33 -> 0
A33: Total cotisation travailleur | C33: =SUMIF([1]!liste_paiement[Trimestre paiement],$M$1,[1]!liste_paiement[CNaPS]) -> 0
A34: Majoration de retard | C34: - | F34: Majoration de retard | I34: =C34 -> -
A35: Net à payer | C35: =SUM(C32:D33) -> 0 | F35: Net à payer | I35: =I32 -> 0
A36: Date de versement | D36: 45680 | F36: Date de versement | I36: =D36 -> 45680
A37: Total effectif travailleurs | D37: =MAX(COUNTIF([1]!liste_paiement[Mois paiement],$M$1),COUNTIF([1]!liste_paiement[Mois paiement],EDATE($M$1,1)),,COUNTIF([1]!liste_paiement[Mois paiement],EDATE($M$1,2))) -> 0 | F37: Total effectif travailleurs | I37: =D37 -> 0
A38: (Listés dans DNS) | F38: (Listés dans DNS)
A40: MODE DE VERSEMENT | F40: MODE DE VERSEMENT
A41: 0 - Trésor Chèque N°
B42: Avis de crédit
A43: 1 - Espèce avec reçu N° | F43: 1 - Espèce avec reçu N°
A44: 2 - Chèque N° | F44: 2 - Chèque N°
A45: 3 - Virement N° | F45: 3 - Virement N°
A46: 4 Virement postal
...
